## 错误处理机制

**1.Error实例对象**

> js解析或运行时，抛出的错误是构造函数的实例

```javascript
> var err = new Error('出错了');
undefined
> err.message;
'出错了'
```

`Error`对象属性

> `message`:错误提示信息,必须项
>
> `name`:错误名称
>
> `stack`：错误发生时的堆栈

```javascript
function throwit(){
	throw new Error('错误');
}

function catchit(){
	try{
		throwit();
	}catch(e){
		console.log(e.name,' ',e.message,' ',e.stack);
	}
}
catchit();
//错误堆栈的最内层是throwit函数，然后是catchit函数，最后是函数的运行环境

// 	 Error   错误   Error: 错误
//     at throwit (G:\es6\eventHandle.js:2:8)
//     at catchit (G:\es6\eventHandle.js:7:3)
//     at Object.<anonymous> (G:\es6\eventHandle.js:12:1)
//     at Module._compile (internal/modules/cjs/loader.js:956:30)
//     at Object.Module._extensions..js (internal/modules/cjs/loader.js:973:10)
//     at Module.load (internal/modules/cjs/loader.js:812:32)
//     at Function.Module._load (internal/modules/cjs/loader.js:724:14)
//     at Function.Module.runMain (internal/modules/cjs/loader.js:1025:10)

```

**2.原生错误类型：`Error`的6个派生对象**

> `SyntaxError对象`:语法错误
>
> `ReferenceError`:引用不存在的变量时发生的错误
>
> ​							将值分配给无法分配的对象
>
> `RangeError`:值超出有效范围，
>
> 主要情况：数组长度为负，Number参数超出范围，函数堆栈超出最大值
>
> `TypeError`:对象是变量或参数不是预期类型时发生的错误
>
> `URIError`：URI相关函数参数不对时抛出的错误
>
> 主要涉及:`encodeURI(),decodeURI(),encodeURIComponent(),decodeURIComponent(),escape(),unescape()`
>
> `EvalError`：`eval`未正常执行时抛出

以上6个错误构造函数均可使用new生成对象

**3.自定义错误**

```javascript
function UserError(message){
	this.message = message||"默认错误";
	this.name = 'UserError';
}
UserError.prototype = new Error();
UserError.prototype.constructor = UserError;

console.log(new UserError("自定义错误"));
// Error
//     at Object.<anonymous> (G:\es6\eventHandle.js:27:23)
//     at Module._compile (internal/modules/cjs/loader.js:956:30)
//     at Object.Module._extensions..js (internal/modules/cjs/loader.js:973:10)
//     at Module.load (internal/modules/cjs/loader.js:812:32)
//     at Function.Module._load (internal/modules/cjs/loader.js:724:14)
//     at Function.Module.runMain (internal/modules/cjs/loader.js:1025:10)
//     at internal/main/run_main_module.js:17:11 {
//   message: '自定义错误',
//   name: 'UserError'
// }
```

**4.throw语句**：手动中断程序执行，抛出一个错误

`throw`可以任何类型的值，参数可以是任何值

```javascript
var x = -1;
if(x<=0){
	throw new Error('Error实例，x必须为整数。');
}
// G:\es6\eventHandle.js:45
//         throw new Error('Error实例，x必须为整数。');
//         ^

// Error: Error实例，x必须为整数。
//     at Object.<anonymous> (G:\es6\eventHandle.js:45:8)
// [90m    at Module._compile (internal/modules/cjs/loader.js:956:30)[39m
// [90m    at Object.Module._extensions..js (internal/modules/cjs/loader.js:973:10)[39m
// [90m    at Module.load (internal/modules/cjs/loader.js:812:32)[39m
// [90m    at Function.Module._load (internal/modules/cjs/loader.js:724:14)[39m
// [90m    at Function.Module.runMain (internal/modules/cjs/loader.js:1025:10)[39m
// [90m    at internal/main/run_main_module.js:17:11[39m

function UserError(message){
	this.message = message || "default error";
	this.name = 'UserError';
}
throw new UserError("自定义错误");
// throw new UserError("自定义错误");
// ^
// UserError { message: [32m'自定义错误'[39m, name: [32m'UserError'[39m }

> throw 'Error!';
Thrown: 'Error!'
> throw 33
Thrown: 33
> throw true;
Thrown: true
> throw {toString:function(){
... return '抛出对象';
... }
... };
Thrown: { toString: [Function: toString] }
```

5.try...catch结构 ，如果try错误就运行catch代码块，catch捕获错误后，程序不会中断，按正常流程继续运行

```javascript
try{
    f();
}catch(e){
    //处理错误
}
```

**6.finally**：不论是否出现错误都必须运行的语句

```javascript
function cleanUp{
    try
}
```

```javascript
//如果try抛出错误，没有catch块，代码中断执行前先运行finally
function cleanUp(){
	try{
		throw new Error('出错了...');
		console.log('此行不执行');
	}
	finally{
		console.log('完成清理工作');
	}
}
cleanUp();
// 完成清理工作
// G:\es6\eventHandle.js:71
//                 throw new Error('出错了...');
//                 ^

// Error: 出错了...
//     at cleanUp (G:\es6\eventHandle.js:71:9)
//     at Object.<anonymous> (G:\es6\eventHandle.js:78:1)
//     at Module._compile (internal/modules/cjs/loader.js:956:30)
//     at Object.Module._extensions..js (internal/modules/cjs/loader.js:973:10)
//     at Module.load (internal/modules/cjs/loader.js:812:32)
//     at Function.Module._load (internal/modules/cjs/loader.js:724:14)
//     at Function.Module.runMain (internal/modules/cjs/loader.js:1025:10)
//     at internal/main/run_main_module.js:17:11
```

```javascript
//如果try抛出错误，有catch块，顺序执行
function cleanUp(){
	try{
		throw new Error('出错了...');
		console.log('此行不执行');
	}
	catch(e){
		console.log(e);
	}
	finally{
		console.log('完成清理工作');
	}
}
cleanUp();
//Error: 出错了...
//     at cleanUp (G:\es6\eventHandle.js:71:9)
//     at Object.<anonymous> (G:\es6\eventHandle.js:80:1)
//     at Module._compile (internal/modules/cjs/loader.js:956:30)
//     at Object.Module._extensions..js (internal/modules/cjs/loader.js:973:10)
//     at Module.load (internal/modules/cjs/loader.js:812:32)
//     at Function.Module._load (internal/modules/cjs/loader.js:724:14)
//     at Function.Module.runMain (internal/modules/cjs/loader.js:1025:10)
//     at internal/main/run_main_module.js:17:11
// 完成清理工作
```

```javascript
//如果try没出错，先finally,再return;
var count = 0;
function countUp(){
	try{
		return count;
	}finally{
		count++;
	}
}
countUp();
console.log(count);	//1
```

**finally典型使用场景**

```javascript
openFile();
try{
    writeFile(Data);
}catch(e){
    handleError(e);
}finally{
    closeFile();
}
//如果try没有错误，try->finally,
//如果try有错误,catch->finally
```

catch代码块触发转入finally代码块的错误，有return 语句，throw语句

try可以嵌套try语句

```javascript
try{
	try{
		log('hello world');//log未定义
	}
	finally{
		console.log('Finally');
	}
	console.log('Will I run?');	//不执行
}catch(e){
	console.log(e.message);	//输出错误
}
// Finally
// log is not defined
```

